<?xml version="1.0"?>
<robot xmlns:xacro="http://www.ros.org/wiki/xacro" name="example">
    <link name="link_0">
        <visual>
            <origin rpy="1.571 0 0" xyz="0.0 0.0 0.0" />
            <geometry>
                <mesh filename="package://testkit/meshes/Transport_TestKit_Plate.stl" scale="0.001 0.001 0.001"/>
            </geometry>
        </visual>
    </link>

    <link name="link_1">
        <visual>
            <origin rpy="0 0 0" xyz="-0.035 -0.035 0.0" />
            <geometry>
                <mesh filename="package://testkit/meshes/Psuedo_Wheel.stl" scale="0.001 0.001 0.001"/>
            </geometry>
        </visual>
    </link>

    <link name="link_2">
        <visual>
            <origin rpy="0 0 0" xyz="-0.035 -0.035 0.0" />
            <geometry>
                <mesh filename="package://testkit/meshes/Psuedo_Wheel.stl" scale="0.001 0.001 0.001"/>
            </geometry>
        </visual>
    </link>

    <link name="link_3">
        <visual>
            <origin rpy="0 0 0" xyz="-0.035 -0.035 0.0" />
            <geometry>
                <mesh filename="package://testkit/meshes/Psuedo_Wheel.stl" scale="0.001 0.001 0.001"/>
            </geometry>
        </visual>
    </link>

    <link name="link_4">
        <visual>
            <origin rpy="0 0 0" xyz="-0.035 -0.035 0.0" />
            <geometry>
                <mesh filename="package://testkit/meshes/Psuedo_Wheel.stl" scale="0.001 0.001 0.001"/>
            </geometry>
        </visual>
    </link>

    <joint name="link_0_to_link_1" type="continuous">
        <parent link="link_0" />
        <child link="link_1" />
        <limit effort="1000.0" lower="0.0" upper="6.28" velocity="0.5" />
        <axis xyz="0 0 1" />
        <origin xyz="0 0.07 -0.14" rpy="-1.571 0 0"/>
    </joint>

    <joint name="link_0_to_link_2" type="continuous">
        <parent link="link_0" />
        <child link="link_2" />
        <limit effort="1000.0" lower="0.0" upper="6.28" velocity="0.5" />
        <axis xyz="0 0 1" />
        <origin xyz="0 -0.6 -0.14" rpy="1.571 0 0"/>
    </joint>

    <joint name="link_0_to_link_3" type="continuous">
        <parent link="link_0" />
        <child link="link_3" />
        <limit effort="1000.0" lower="0.0" upper="6.28" velocity="0.5" />
        <axis xyz="0 0 1" />
        <origin xyz="0.69 0.07 -0.14" rpy="-1.571 0 0"/>
    </joint>

    <joint name="link_0_to_link_4" type="continuous">
        <parent link="link_0" />
        <child link="link_4" />
        <limit effort="1000.0" lower="0.0" upper="6.28" velocity="0.5" />
        <axis xyz="0 0 1" />
        <origin xyz="0.69 -0.6 -0.14" rpy="1.571 0 0"/>
    </joint>


</robot>